<?xml version="1.0" ?>
<!-- =================================================================================== -->
<!-- |    This document was autogenerated by xacro from /home/ubuntu/zuko/quad_ws/src/quad_udrf/urdf/zuko.urdf.xacro | -->
<!-- |    EDITING THIS FILE BY HAND IS NOT RECOMMENDED                                 | -->
<!-- =================================================================================== -->
<robot name="zuko">
  <!--
<xacro:include filename="$(find quad_urdf)/urdf/zuko_hips_and_legs.urdf.xacro" />
-->
  <material name="brown">
    <color rgba="0.588 0.294 0.0 1"/>
  </material>
  <material name="black">
    <color rgba="0.1 0.1 0.1 1"/>
  </material>
  <material name="white">
    <color rgba="1 1 1 1"/>
  </material>
  <!-- STATIC Links -->
  <link name="base_link">
    <visual>
      <origin rpy="1.5707963267948966 0 -1.5707963267948966" xyz="-0.0025 0 0"/>
      <geometry>
        <mesh filename="package://stl/center_front.stl" scale="1 1 1"/>
      </geometry>
      <material name="brown"/>
    </visual>
    <collision>
      <origin rpy="1.5707963267948966 0 -1.5707963267948966" xyz="0 0 0"/>
      <geometry>
        <box size="0 0 0"/>
      </geometry>
    </collision>
    <inertial>
      <mass value="0.6"/>
      <origin rpy="0 0 0" xyz="0 0 0"/>
      <!-- Inertial Axes -->
      <inertia ixx="0.0" ixy="0" ixz="0" iyx="0" iyy="0.0" iyz="0" izx="0" izy="0" izz="0.0"/>
    </inertial>
  </link>
  <gazebo reference="base_link">
  </gazebo>
  <link name="side_left_link">
    <visual>
      <origin rpy="1.5707963267948966 0 1.5707963267948966" xyz="0 0 0"/>
      <geometry>
        <mesh filename="package://stl/side_left.stl" scale="1 1 1"/>
      </geometry>
      <material name="brown"/>
    </visual>
    <collision>
      <origin rpy="1.5707963267948966 0 1.5707963267948966" xyz="0 0 0"/>
      <geometry>
        <box size="0 0 0"/>
      </geometry>
    </collision>
    <inertial>
      <mass value="0.6"/>
      <origin rpy="0 0 0" xyz="0 0 0"/>
      <!-- Inertial Axes -->
      <inertia ixx="0.0" ixy="0" ixz="0" iyx="0" iyy="0.0" iyz="0" izx="0" izy="0" izz="0.0"/>
    </inertial>
  </link>
  <gazebo reference="side_left_link">
  </gazebo>
  <link name="side_right_link">
    <visual>
      <origin rpy="1.5707963267948966 0 -1.5707963267948966" xyz="0 0 0"/>
      <geometry>
        <mesh filename="package://stl/side_right.stl" scale="1 1 1"/>
      </geometry>
      <material name="brown"/>
    </visual>
    <collision>
      <origin rpy="1.5707963267948966 0 -1.5707963267948966" xyz="0 0 0"/>
      <geometry>
        <box size="0 0 0"/>
      </geometry>
    </collision>
    <inertial>
      <mass value="0.6"/>
      <origin rpy="0 0 0" xyz="0 0 0"/>
      <!-- Inertial Axes -->
      <inertia ixx="0.0" ixy="0" ixz="0" iyx="0" iyy="0.0" iyz="0" izx="0" izy="0" izz="0.0"/>
    </inertial>
  </link>
  <gazebo reference="side_right_link">
  </gazebo>
  <link name="center_back_link">
    <visual>
      <origin rpy="1.5707963267948966 0 1.5707963267948966" xyz="0.0025 0 0"/>
      <geometry>
        <mesh filename="package://stl/center_back.stl" scale="1 1 1"/>
      </geometry>
      <material name="brown"/>
    </visual>
    <collision>
      <origin rpy="1.5707963267948966 0 1.5707963267948966" xyz="0 0 0"/>
      <geometry>
        <box size="0 0 0"/>
      </geometry>
    </collision>
    <inertial>
      <mass value="0.6"/>
      <origin rpy="0 0 0" xyz="0 0 0"/>
      <!-- Inertial Axes -->
      <inertia ixx="0.0" ixy="0" ixz="0" iyx="0" iyy="0.0" iyz="0" izx="0" izy="0" izz="0.0"/>
    </inertial>
  </link>
  <gazebo reference="center_back_link">
  </gazebo>
  <link name="bridge_front_link">
    <visual>
      <origin rpy="1.5707963267948966 0 -1.5707963267948966" xyz="0 0 0"/>
      <geometry>
        <mesh filename="package://stl/bridge_front.stl" scale="1 1 1"/>
      </geometry>
      <material name="white"/>
    </visual>
    <collision>
      <origin rpy="1.5707963267948966 0 -1.5707963267948966" xyz="0 0 0"/>
      <geometry>
        <box size="0 0 0"/>
      </geometry>
    </collision>
    <inertial>
      <mass value="0.6"/>
      <origin rpy="0 0 0" xyz="0 0 0"/>
      <!-- Inertial Axes -->
      <inertia ixx="0.0" ixy="0" ixz="0" iyx="0" iyy="0.0" iyz="0" izx="0" izy="0" izz="0.0"/>
    </inertial>
  </link>
  <gazebo reference="bridge_front_link">
  </gazebo>
  <link name="bridge_back_link">
    <visual>
      <origin rpy="1.5707963267948966 0 -1.5707963267948966" xyz="0 0 0"/>
      <geometry>
        <mesh filename="package://stl/bridge_back.stl" scale="1 1 1"/>
      </geometry>
      <material name="white"/>
    </visual>
    <collision>
      <origin rpy="1.5707963267948966 0 -1.5707963267948966" xyz="0 0 0"/>
      <geometry>
        <box size="0 0 0"/>
      </geometry>
    </collision>
    <inertial>
      <mass value="0.6"/>
      <origin rpy="0 0 0" xyz="0 0 0"/>
      <!-- Inertial Axes -->
      <inertia ixx="0.0" ixy="0" ixz="0" iyx="0" iyy="0.0" iyz="0" izx="0" izy="0" izz="0.0"/>
    </inertial>
  </link>
  <gazebo reference="bridge_back_link">
  </gazebo>
  <link name="face_link">
    <visual>
      <origin rpy="1.5707963267948966 0 1.5707963267948966" xyz="0 0 0"/>
      <geometry>
        <mesh filename="package://stl/face.stl" scale="1 1 1"/>
      </geometry>
      <material name="brown"/>
    </visual>
    <collision>
      <origin rpy="1.5707963267948966 0 1.5707963267948966" xyz="0 0 0"/>
      <geometry>
        <box size="0 0 0"/>
      </geometry>
    </collision>
    <inertial>
      <mass value="0.6"/>
      <origin rpy="0 0 0" xyz="0 0 0"/>
      <!-- Inertial Axes -->
      <inertia ixx="0.0" ixy="0" ixz="0" iyx="0" iyy="0.0" iyz="0" izx="0" izy="0" izz="0.0"/>
    </inertial>
  </link>
  <gazebo reference="face_link">
  </gazebo>
  <link name="butt_link">
    <visual>
      <origin rpy="1.5707963267948966 0 -1.5707963267948966" xyz="0 0 0"/>
      <geometry>
        <mesh filename="package://stl/butt.stl" scale="1 1 1"/>
      </geometry>
      <material name="brown"/>
    </visual>
    <collision>
      <origin rpy="1.5707963267948966 0 -1.5707963267948966" xyz="0 0 0"/>
      <geometry>
        <box size="0 0 0"/>
      </geometry>
    </collision>
    <inertial>
      <mass value="0.6"/>
      <origin rpy="0 0 0" xyz="0 0 0"/>
      <!-- Inertial Axes -->
      <inertia ixx="0.0" ixy="0" ixz="0" iyx="0" iyy="0.0" iyz="0" izx="0" izy="0" izz="0.0"/>
    </inertial>
  </link>
  <gazebo reference="butt_link">
  </gazebo>
  <!-- STATIC Joints -->
  <joint name="side_left_joint" type="fixed">
    <origin rpy="0 0 0" xyz="-0.16599999999999998 0.060 0.015"/>
    <parent link="base_link"/>
    <child link="side_left_link"/>
  </joint>
  <joint name="side_right_joint" type="fixed">
    <origin rpy="0 0 0" xyz="-0.018 -0.060 0.015"/>
    <parent link="base_link"/>
    <child link="side_right_link"/>
  </joint>
  <joint name="center_back_joint" type="fixed">
    <origin rpy="0 0 0" xyz="-0.18399999999999997 0 0"/>
    <parent link="base_link"/>
    <child link="center_back_link"/>
  </joint>
  <joint name="bridge_front_joint" type="fixed">
    <origin rpy="0 0  0" xyz="0.0535 0 -0.011"/>
    <parent link="base_link"/>
    <child link="bridge_front_link"/>
  </joint>
  <joint name="bridge_back_joint" type="fixed">
    <origin rpy="0 0 0" xyz="0 0 -0.011"/>
    <parent link="center_back_link"/>
    <child link="bridge_back_link"/>
  </joint>
  <joint name="face_joint" type="fixed">
    <origin rpy="0 0 0" xyz="0 0 0"/>
    <parent link="bridge_front_link"/>
    <child link="face_link"/>
  </joint>
  <joint name="butt_joint" type="fixed">
    <origin rpy="0 0 0" xyz="-0.0535 0 0"/>
    <parent link="bridge_back_link"/>
    <child link="butt_link"/>
  </joint>
  <!-- Hips/Legs Links/Joints -->
  <link name="front_left_hip_link">
    <visual>
      <origin rpy="0 0 0" xyz="0 0 0"/>
      <geometry>
        <mesh filename="package://stl/hip_front.stl" scale="1 1 1"/>
      </geometry>
      <material name="white"/>
    </visual>
    <collision>
      <origin rpy="0 0 0" xyz="0 0 0"/>
      <geometry>
        <box size="0 0 0"/>
      </geometry>
    </collision>
    <inertial>
      <mass value="0.6"/>
      <origin rpy="0 0 0" xyz="0 0 0"/>
      <!-- Inertial Axes -->
      <inertia ixx="0.0" ixy="0" ixz="0" iyx="0" iyy="0.0" iyz="0" izx="0" izy="0" izz="0.0"/>
    </inertial>
  </link>
  <gazebo reference="front_left_hip_link">
  </gazebo>
  <joint name="front_left_hip_rev_joint" type="revolute">
    <axis xyz="-1 0 0"/>
    <origin rpy="0 0 3.141592653589793" xyz="0.002 0.0455 0"/>
    <parent link="base_link"/>
    <child link="front_left_hip_link"/>
    <limit effort="4.0" lower="-0.5235987755982988" upper="0.5235987755982988" velocity="4.0"/>
    <joint_properties damping="0.0" friction="0.0"/>
  </joint>
  <link name="front_left_upper_leg_link">
    <visual>
      <origin rpy="-1.5707963267948966 1.5707963267948966 0" xyz="0 0 0"/>
      <geometry>
        <mesh filename="package://stl/upper_leg.stl" scale="1 1 1"/>
      </geometry>
      <material name="brown"/>
    </visual>
    <collision>
      <origin rpy="-1.5707963267948966 1.5707963267948966 0" xyz="0 0 0"/>
      <geometry>
        <box size="0 0 0"/>
      </geometry>
    </collision>
    <inertial>
      <mass value="0.6"/>
      <origin rpy="0 0 0" xyz="0 0 0"/>
      <!-- Inertial Axes -->
      <inertia ixx="0.0" ixy="0" ixz="0" iyx="0" iyy="0.0" iyz="0" izx="0" izy="0" izz="0.0"/>
    </inertial>
  </link>
  <gazebo reference="front_left_upper_leg_link">
  </gazebo>
  <joint name="front_left_upper_leg_rev_joint" type="revolute">
    <axis xyz="0 1 0"/>
    <origin rpy="0 0 3.141592653589793" xyz="-0.0145 -0.03175 0"/>
    <parent link="front_left_hip_link"/>
    <child link="front_left_upper_leg_link"/>
    <limit effort="4.0" lower="0.0" upper="1.9198621771937625" velocity="4.0"/>
    <joint_properties damping="0.0" friction="0.0"/>
  </joint>
  <link name="front_left_lower_leg_link">
    <visual>
      <origin rpy="1.5707963267948966 1.5707963267948966 3.141592653589793" xyz="0 -0.0075 0"/>
      <geometry>
        <mesh filename="package://stl/lower_leg.stl" scale="1 1 1"/>
      </geometry>
      <material name="brown"/>
    </visual>
    <collision>
      <origin rpy="1.5707963267948966 1.5707963267948966 3.141592653589793" xyz="0 0 0"/>
      <geometry>
        <box size="0 0 0"/>
      </geometry>
    </collision>
    <inertial>
      <mass value="0.6"/>
      <origin rpy="0 0 0" xyz="0 0 0"/>
      <!-- Inertial Axes -->
      <inertia ixx="0.0" ixy="0" ixz="0" iyx="0" iyy="0.0" iyz="0" izx="0" izy="0" izz="0.0"/>
    </inertial>
  </link>
  <gazebo reference="front_left_lower_leg_link">
  </gazebo>
  <joint name="front_left_lower_leg_rev_joint" type="revolute">
    <axis xyz="0 -1 0"/>
    <origin rpy="0 0 3.141592653589793" xyz="0 0 -0.1"/>
    <parent link="front_left_upper_leg_link"/>
    <child link="front_left_lower_leg_link"/>
    <limit effort="4.0" lower="-3.141592653589793" upper="3.141592653589793" velocity="4.0"/>
    <joint_properties damping="0.0" friction="0.0"/>
  </joint>
  <link name="front_right_hip_link">
    <visual>
      <origin rpy="0 0 0" xyz="0 0 0"/>
      <geometry>
        <mesh filename="package://stl/hip_front.stl" scale="1 -1 1"/>
      </geometry>
      <material name="white"/>
    </visual>
    <collision>
      <origin rpy="0 0 0" xyz="0 0 0"/>
      <geometry>
        <box size="0 0 0"/>
      </geometry>
    </collision>
    <inertial>
      <mass value="0.6"/>
      <origin rpy="0 0 0" xyz="0 0 0"/>
      <!-- Inertial Axes -->
      <inertia ixx="0.0" ixy="0" ixz="0" iyx="0" iyy="0.0" iyz="0" izx="0" izy="0" izz="0.0"/>
    </inertial>
  </link>
  <gazebo reference="front_right_hip_link">
  </gazebo>
  <joint name="front_right_hip_rev_joint" type="revolute">
    <axis xyz="-1 0 0"/>
    <origin rpy="0 0 3.141592653589793" xyz="0.002 -0.0455 0"/>
    <parent link="base_link"/>
    <child link="front_right_hip_link"/>
    <limit effort="4.0" lower="-0.5235987755982988" upper="0.5235987755982988" velocity="4.0"/>
    <joint_properties damping="0.0" friction="0.0"/>
  </joint>
  <link name="front_right_upper_leg_link">
    <visual>
      <origin rpy="-1.5707963267948966 1.5707963267948966 3.141592653589793" xyz="0 0 0"/>
      <geometry>
        <mesh filename="package://stl/upper_leg.stl" scale="1 1 1"/>
      </geometry>
      <material name="brown"/>
    </visual>
    <collision>
      <origin rpy="-1.5707963267948966 1.5707963267948966 3.141592653589793" xyz="0 0 0"/>
      <geometry>
        <box size="0 0 0"/>
      </geometry>
    </collision>
    <inertial>
      <mass value="0.6"/>
      <origin rpy="0 0 0" xyz="0 0 0"/>
      <!-- Inertial Axes -->
      <inertia ixx="0.0" ixy="0" ixz="0" iyx="0" iyy="0.0" iyz="0" izx="0" izy="0" izz="0.0"/>
    </inertial>
  </link>
  <gazebo reference="front_right_upper_leg_link">
  </gazebo>
  <joint name="front_right_upper_leg_rev_joint" type="revolute">
    <axis xyz="0 1 0"/>
    <origin rpy="0 0 3.141592653589793" xyz="-0.0145 0.03175 0"/>
    <parent link="front_right_hip_link"/>
    <child link="front_right_upper_leg_link"/>
    <limit effort="4.0" lower="0.0" upper="1.9198621771937625" velocity="4.0"/>
    <joint_properties damping="0.0" friction="0.0"/>
  </joint>
  <link name="front_right_lower_leg_link">
    <visual>
      <origin rpy="1.5707963267948966 1.5707963267948966  3.141592653589793" xyz="0 0.0075 0"/>
      <geometry>
        <mesh filename="package://stl/lower_leg.stl" scale="1 1 -1"/>
      </geometry>
      <material name="brown"/>
    </visual>
    <collision>
      <origin rpy="1.5707963267948966 1.5707963267948966  3.141592653589793" xyz="0 0 -0.06"/>
      <geometry>
        <box size="0 0 0"/>
      </geometry>
    </collision>
    <inertial>
      <mass value="0.6"/>
      <origin rpy="0 0 0" xyz="0 0 0"/>
      <!-- Inertial Axes -->
      <inertia ixx="0.0" ixy="0" ixz="0" iyx="0" iyy="0.0" iyz="0" izx="0" izy="0" izz="0.0"/>
    </inertial>
  </link>
  <gazebo reference="front_right_lower_leg_link">
  </gazebo>
  <joint name="front_right_lower_leg_rev_joint" type="revolute">
    <axis xyz="0 -1 0"/>
    <origin rpy="0 0 3.141592653589793" xyz="0 0 -0.1"/>
    <parent link="front_right_upper_leg_link"/>
    <child link="front_right_lower_leg_link"/>
    <limit effort="4.0" lower="-3.141592653589793" upper="3.141592653589793" velocity="4.0"/>
    <joint_properties damping="0.0" friction="0.0"/>
  </joint>
  <link name="back_left_hip_link">
    <visual>
      <origin rpy="0 0 3.141592653589793" xyz="0 0 0"/>
      <geometry>
        <mesh filename="package://stl/hip_back.stl" scale="1 1 1"/>
      </geometry>
      <material name="white"/>
    </visual>
    <collision>
      <origin rpy="0 0 3.141592653589793" xyz="0 0 0"/>
      <geometry>
        <box size="0 0 0"/>
      </geometry>
    </collision>
    <inertial>
      <mass value="0.6"/>
      <origin rpy="0 0 0" xyz="0 0 0"/>
      <!-- Inertial Axes -->
      <inertia ixx="0.0" ixy="0" ixz="0" iyx="0" iyy="0.0" iyz="0" izx="0" izy="0" izz="0.0"/>
    </inertial>
  </link>
  <gazebo reference="back_left_hip_link">
  </gazebo>
  <joint name="back_left_hip_rev_joint" type="revolute">
    <axis xyz="1 0 0"/>
    <origin rpy="0 0 0" xyz="-0.002 0.0455 0"/>
    <parent link="center_back_link"/>
    <child link="back_left_hip_link"/>
    <limit effort="4.0" lower="-0.5235987755982988" upper="0.5235987755982988" velocity="4.0"/>
    <joint_properties damping="0.0" friction="0.0"/>
  </joint>
  <link name="back_left_upper_leg_link">
    <visual>
      <origin rpy="-1.5707963267948966 1.5707963267948966 0" xyz="0 0 0"/>
      <geometry>
        <mesh filename="package://stl/upper_leg.stl" scale="1 1 1"/>
      </geometry>
      <material name="brown"/>
    </visual>
    <collision>
      <origin rpy="-1.5707963267948966 1.5707963267948966 0" xyz="0 0 0"/>
      <geometry>
        <box size="0 0 0"/>
      </geometry>
    </collision>
    <inertial>
      <mass value="0.6"/>
      <origin rpy="0 0 0" xyz="0 0 0"/>
      <!-- Inertial Axes -->
      <inertia ixx="0.0" ixy="0" ixz="0" iyx="0" iyy="0.0" iyz="0" izx="0" izy="0" izz="0.0"/>
    </inertial>
  </link>
  <gazebo reference="back_left_upper_leg_link">
  </gazebo>
  <joint name="back_left_upper_leg_rev_joint" type="revolute">
    <axis xyz="0 1 0"/>
    <origin rpy="0 0 0" xyz="-0.035500000000000004 0.03175 0"/>
    <parent link="back_left_hip_link"/>
    <child link="back_left_upper_leg_link"/>
    <limit effort="4.0" lower="0.0" upper="1.9198621771937625" velocity="4.0"/>
    <joint_properties damping="0.0" friction="0.0"/>
  </joint>
  <link name="back_left_lower_leg_link">
    <visual>
      <origin rpy="1.5707963267948966 1.5707963267948966 3.141592653589793" xyz="0 -0.0075 0"/>
      <geometry>
        <mesh filename="package://stl/lower_leg.stl" scale="1 1 1"/>
      </geometry>
      <material name="brown"/>
    </visual>
    <collision>
      <origin rpy="1.5707963267948966 1.5707963267948966 3.141592653589793" xyz="0 0 0"/>
      <geometry>
        <box size="0 0 0"/>
      </geometry>
    </collision>
    <inertial>
      <mass value="0.6"/>
      <origin rpy="0 0 0" xyz="0 0 0"/>
      <!-- Inertial Axes -->
      <inertia ixx="0.0" ixy="0" ixz="0" iyx="0" iyy="0.0" iyz="0" izx="0" izy="0" izz="0.0"/>
    </inertial>
  </link>
  <gazebo reference="back_left_lower_leg_link">
  </gazebo>
  <joint name="back_left_lower_leg_rev_joint" type="revolute">
    <axis xyz="0 -1 0"/>
    <origin rpy="0 0 3.141592653589793" xyz="0 0 -0.1"/>
    <parent link="back_left_upper_leg_link"/>
    <child link="back_left_lower_leg_link"/>
    <limit effort="4.0" lower="-3.141592653589793" upper="3.141592653589793" velocity="4.0"/>
    <joint_properties damping="0.0" friction="0.0"/>
  </joint>
  <link name="back_right_hip_link">
    <visual>
      <origin rpy="0 0 3.141592653589793" xyz="0 0 0"/>
      <geometry>
        <mesh filename="package://stl/hip_back.stl" scale="1 -1 1"/>
      </geometry>
      <material name="white"/>
    </visual>
    <collision>
      <origin rpy="0 0 3.141592653589793" xyz="0 0 0"/>
      <geometry>
        <box size="0 0 0"/>
      </geometry>
    </collision>
    <inertial>
      <mass value="0.6"/>
      <origin rpy="0 0 0" xyz="0 0 0"/>
      <!-- Inertial Axes -->
      <inertia ixx="0.0" ixy="0" ixz="0" iyx="0" iyy="0.0" iyz="0" izx="0" izy="0" izz="0.0"/>
    </inertial>
  </link>
  <gazebo reference="back_right_hip_link">
  </gazebo>
  <joint name="back_right_hip_rev_joint" type="revolute">
    <axis xyz="1 0 0"/>
    <origin rpy="0 0 0" xyz="-0.002 -0.0455 0"/>
    <parent link="center_back_link"/>
    <child link="back_right_hip_link"/>
    <limit effort="4.0" lower="-0.5235987755982988" upper="0.5235987755982988" velocity="4.0"/>
    <joint_properties damping="0.0" friction="0.0"/>
  </joint>
  <link name="back_right_upper_leg_link">
    <visual>
      <origin rpy="-1.5707963267948966 1.5707963267948966 3.141592653589793 " xyz="0 0 0"/>
      <geometry>
        <mesh filename="package://stl/upper_leg.stl" scale="1 1 1"/>
      </geometry>
      <material name="brown"/>
    </visual>
    <collision>
      <origin rpy="-1.5707963267948966 1.5707963267948966 3.141592653589793 " xyz="0 0 0"/>
      <geometry>
        <box size="0 0 0"/>
      </geometry>
    </collision>
    <inertial>
      <mass value="0.6"/>
      <origin rpy="0 0 0" xyz="0 0 0"/>
      <!-- Inertial Axes -->
      <inertia ixx="0.0" ixy="0" ixz="0" iyx="0" iyy="0.0" iyz="0" izx="0" izy="0" izz="0.0"/>
    </inertial>
  </link>
  <gazebo reference="back_right_upper_leg_link">
  </gazebo>
  <joint name="back_right_upper_leg_rev_joint" type="revolute">
    <axis xyz="0 1 0"/>
    <origin rpy="0 0 0" xyz="-0.035500000000000004 -0.03175 0"/>
    <parent link="back_right_hip_link"/>
    <child link="back_right_upper_leg_link"/>
    <limit effort="4.0" lower="0.0" upper="1.9198621771937625" velocity="4.0"/>
    <joint_properties damping="0.0" friction="0.0"/>
  </joint>
  <link name="back_right_lower_leg_link">
    <visual>
      <origin rpy="1.5707963267948966 1.5707963267948966 3.141592653589793" xyz="0 0.0075 0"/>
      <geometry>
        <mesh filename="package://stl/lower_leg.stl" scale="1 1 -1"/>
      </geometry>
      <material name="brown"/>
    </visual>
    <collision>
      <origin rpy="1.5707963267948966 1.5707963267948966 3.141592653589793" xyz="0  -0.06 0"/>
      <geometry>
        <box size="0 0 0"/>
      </geometry>
    </collision>
    <inertial>
      <mass value="0.6"/>
      <origin rpy="0 0 0" xyz="0 0 0"/>
      <!-- Inertial Axes -->
      <inertia ixx="0.0" ixy="0" ixz="0" iyx="0" iyy="0.0" iyz="0" izx="0" izy="0" izz="0.0"/>
    </inertial>
  </link>
  <gazebo reference="back_right_lower_leg_link">
  </gazebo>
  <joint name="back_right_lower_leg_rev_joint" type="revolute">
    <axis xyz="0 -1 0"/>
    <origin rpy="0 0 3.141592653589793" xyz="0 0 -0.1"/>
    <parent link="back_right_upper_leg_link"/>
    <child link="back_right_lower_leg_link"/>
    <limit effort="4.0" lower="-3.141592653589793" upper="3.141592653589793" velocity="4.0"/>
    <joint_properties damping="0.0" friction="0.0"/>
  </joint>
  <!--
<xacro:transmission leg="front_left"/>
<xacro:transmission leg="front_right"/>
<xacro:transmission leg="back_left"/>
<xacro:transmission leg="back_right"/>  
-->
</robot>
