<?xml version="1.0" ?>
<!-- =================================================================================== -->
<!-- |    This document was autogenerated by xacro from /home/devpc/Desktop/quad_ws/src/quad/quad/src/urdf/quad.urdf.xacro | -->
<!-- |    EDITING THIS FILE BY HAND IS NOT RECOMMENDED                                 | -->
<!-- =================================================================================== -->
<robot name="spot">
  <material name="orange">
    <color rgba="1.0 0.5 0.0 1"/>
  </material>
  <material name="black">
    <color rgba="0.1 0.1 0.1 1"/>
  </material>
  <material name="grey">
    <color rgba="0.6 0.6 0.6 1"/>
  </material>
  <!-- Left Leg: prefix is front or rear -->
  <!--   <xacro:macro name="LeftLeg" params="prefix reflect">
    <link name="${prefix}_Left_Leg">
        <visual>
            <geometry>
                <box size="${leglen} 0.1 0.2"/>
            </geometry>
            <origin xyz="0 0 -${leglen/2}" rpy="0 ${pi/2} 0"/>
            <material name="white"/>
        </visual>
        <collision>
            <geometry>
                <box size="${leglen} 0.1 0.2"/>
            </geometry>
            <origin xyz="0 0 -${leglen/2}" rpy="0 ${pi/2} 0"/>
        </collision>
        <xacro:default_inertial mass="10"/>
    </link>

    <joint name="base_to_${prefix}_leg" type="fixed">
        <parent link="base_link"/>
        <child link="${prefix}_leg"/>
        <origin xyz="0 ${reflect*(width+.02)} 0.25" />
    </joint>
</xacro:macro> -->
  <!-- Robot description -->
  <!-- STATIC Links -->
  <link name="base_link"/>
  <link name="base_inertia">
    <visual>
      <origin rpy="0 0 1.5707963267948966" xyz="-0.16 0.035 -0.045"/>
      <geometry>
        <mesh filename="package://stl/MAINBODY.stl" scale="1 1 1"/>
      </geometry>
      <material name="orange"/>
    </visual>
    <collision>
      <origin rpy="0 0 1.5707963267948966" xyz="0 0 0"/>
      <geometry>
        <box size="0.114 0.2 0.1"/>
      </geometry>
    </collision>
    <inertial>
      <mass value="0.6"/>
      <origin rpy="0 0 0" xyz="0 0 0"/>
      <!-- Inertial Axes -->
      <inertia ixx="0.0025000000000000005" ixy="0" ixz="0" iyx="0" iyy="0.0011498" iyz="0" izx="0" izy="0" izz="0.0026498000000000003"/>
    </inertial>
  </link>
  <gazebo reference="base_inertia">
    <material>Gazebo/Orange</material>
  </gazebo>
  <!-- m to mm -->
  <link name="battery">
    <visual>
      <origin rpy="0 0 1.5707963267948966" xyz="-0.15 0.035 -0.022"/>
      <geometry>
        <mesh filename="package://stl/Battery.stl" scale="1 1 1"/>
      </geometry>
      <material name="black"/>
    </visual>
    <collision>
      <origin rpy="0 0 1.5707963267948966" xyz="0 0 0"/>
      <geometry>
        <box size="0.048 0.145 0.026"/>
      </geometry>
    </collision>
    <inertial>
      <mass value="0.4"/>
      <origin rpy="0 0 0" xyz="0 0 0"/>
      <!-- Inertial Axes -->
      <inertia ixx="0.0007233666666666667" ixy="0" ixz="0" iyx="0" iyy="9.933333333333334e-05" iyz="0" izx="0" izy="0" izz="0.0007776333333333334"/>
    </inertial>
  </link>
  <gazebo reference="battery">
    <material>Gazebo/Black</material>
  </gazebo>
  <!-- m to mm -->
  <link name="chassis_left">
    <visual>
      <origin rpy="0 1.5707963267948966 -1.5707963267948966" xyz="0.016 0.003 0"/>
      <geometry>
        <mesh filename="package://stl/Chassis_Left_Side.stl" scale="1 1 1"/>
      </geometry>
      <material name="black"/>
    </visual>
    <collision>
      <origin rpy="0 1.5707963267948966 -1.5707963267948966" xyz="0 0 0"/>
      <geometry>
        <box size="0.06 0.15 0.006"/>
      </geometry>
    </collision>
    <inertial>
      <mass value="0.01"/>
      <origin rpy="0 0 0" xyz="0 0 0"/>
      <!-- Inertial Axes -->
      <inertia ixx="1.878e-05" ixy="0" ixz="0" iyx="0" iyy="3.03e-06" iyz="0" izx="0" izy="0" izz="2.175e-05"/>
    </inertial>
  </link>
  <gazebo reference="chassis_left">
    <material>Gazebo/Black</material>
  </gazebo>
  <!-- m to mm -->
  <link name="chassis_right">
    <visual>
      <origin rpy="0 1.5707963267948966 1.5707963267948966" xyz="-0.016 -0.003 0"/>
      <geometry>
        <mesh filename="package://stl/Chassis_Right_Side.stl" scale="1 1 1"/>
      </geometry>
      <material name="black"/>
    </visual>
    <collision>
      <origin rpy="0 1.5707963267948966 1.5707963267948966" xyz="0 0 0"/>
      <geometry>
        <box size="0.06 0.15 0.006"/>
      </geometry>
    </collision>
    <inertial>
      <mass value="0.01"/>
      <origin rpy="0 0 0" xyz="0 0 0"/>
      <!-- Inertial Axes -->
      <inertia ixx="1.878e-05" ixy="0" ixz="0" iyx="0" iyy="3.03e-06" iyz="0" izx="0" izy="0" izz="2.175e-05"/>
    </inertial>
  </link>
  <gazebo reference="chassis_right">
    <material>Gazebo/Black</material>
  </gazebo>
  <!-- m to mm -->
  <link name="front">
    <visual>
      <origin rpy="0 0 1.5707963267948966" xyz="-0.16 0.035 -0.045"/>
      <geometry>
        <mesh filename="package://stl/Front.stl" scale="1 1 1"/>
      </geometry>
      <material name="orange"/>
    </visual>
    <collision>
      <origin rpy="0 0 1.5707963267948966" xyz="0.16 0 0.006"/>
      <geometry>
        <box size="0.114 0.045 0.085"/>
      </geometry>
    </collision>
    <inertial>
      <mass value="0.1"/>
      <origin rpy="0 0 0" xyz="0 0 0"/>
      <!-- Inertial Axes -->
      <inertia ixx="7.708333333333334e-05" ixy="0" ixz="0" iyx="0" iyy="0.00016850833333333334" iyz="0" izx="0" izy="0" izz="0.00012517500000000002"/>
    </inertial>
  </link>
  <gazebo reference="front">
    <material>Gazebo/Orange</material>
  </gazebo>
  <!-- m to mm -->
  <link name="back">
    <visual>
      <origin rpy="0 0 1.5707963267948966" xyz="-0.16 0.035 -0.045"/>
      <geometry>
        <mesh filename="package://stl/Back.stl" scale="1 1 1"/>
      </geometry>
      <material name="orange"/>
    </visual>
    <collision>
      <origin rpy="0 0 1.5707963267948966" xyz="-0.16 0 0.006"/>
      <geometry>
        <box size="0.114 0.075 0.085"/>
      </geometry>
    </collision>
    <inertial>
      <mass value="0.1"/>
      <origin rpy="0 0 0" xyz="0 0 0"/>
      <!-- Inertial Axes -->
      <inertia ixx="0.00010708333333333334" ixy="0" ixz="0" iyx="0" iyy="0.00016850833333333334" iyz="0" izx="0" izy="0" izz="0.000155175"/>
    </inertial>
  </link>
  <gazebo reference="back">
    <material>Gazebo/Orange</material>
  </gazebo>
  <!-- m to mm -->
  <link name="front_bracket">
    <visual>
      <origin rpy="0 0 1.5707963267948966" xyz="-0.16 0.035 -0.045"/>
      <geometry>
        <mesh filename="package://stl/Front_Bracket.stl" scale="1 1 1"/>
      </geometry>
      <material name="black"/>
    </visual>
    <collision>
      <origin rpy="0 0 1.5707963267948966" xyz="0.1 0 0"/>
      <geometry>
        <box size="0.025 0.075 0.085"/>
      </geometry>
    </collision>
    <inertial>
      <mass value="0.1"/>
      <origin rpy="0 0 0" xyz="0 0 0"/>
      <!-- Inertial Axes -->
      <inertia ixx="0.00010708333333333334" ixy="0" ixz="0" iyx="0" iyy="6.541666666666668e-05" iyz="0" izx="0" izy="0" izz="5.2083333333333343e-05"/>
    </inertial>
  </link>
  <gazebo reference="front_bracket">
    <material>Gazebo/Black</material>
  </gazebo>
  <!-- m to mm -->
  <link name="back_bracket">
    <visual>
      <origin rpy="0 0 1.5707963267948966" xyz="-0.16 0.035 -0.045"/>
      <geometry>
        <mesh filename="package://stl/Back_Bracket.stl" scale="1 1 1"/>
      </geometry>
      <material name="black"/>
    </visual>
    <collision>
      <origin rpy="0 0 1.5707963267948966" xyz="-0.1 0 0"/>
      <geometry>
        <box size="0.025 0.075 0.085"/>
      </geometry>
    </collision>
    <inertial>
      <mass value="0.1"/>
      <origin rpy="0 0 0" xyz="0 0 0"/>
      <!-- Inertial Axes -->
      <inertia ixx="0.00010708333333333334" ixy="0" ixz="0" iyx="0" iyy="6.541666666666668e-05" iyz="0" izx="0" izy="0" izz="5.2083333333333343e-05"/>
    </inertial>
  </link>
  <gazebo reference="back_bracket">
    <material>Gazebo/Black</material>
  </gazebo>
  <!-- m to mm -->
  <link name="front_left_hip">
    <visual>
      <origin rpy="0 0 1.5707963267948966" xyz="-0.25 -0.0044 -0.067"/>
      <geometry>
        <mesh filename="package://stl/LEFT_HIP.stl" scale="1 1 1"/>
      </geometry>
      <material name="black"/>
    </visual>
    <collision>
      <origin rpy="0 0 1.5707963267948966" xyz="0.015 0.01 -0.01"/>
      <geometry>
        <box size="0.05 0.065 0.065"/>
      </geometry>
    </collision>
    <inertial>
      <mass value="0.2"/>
      <origin rpy="0 0 0" xyz="0 0.075 0"/>
      <!-- Inertial Axes -->
      <inertia ixx="0.00014083333333333336" ixy="0" ixz="0" iyx="0" iyy="0.00011208333333333335" iyz="0" izx="0" izy="0" izz="0.00011208333333333335"/>
    </inertial>
  </link>
  <gazebo reference="front_left_hip">
    <material>Gazebo/Black</material>
  </gazebo>
  <joint name="motor_front_left_hip" type="revolute">
    <axis xyz="1 0 0"/>
    <origin rpy="0 0 0" xyz="0.0915 0.039400000000000004 0.022000000000000006"/>
    <parent link="front_bracket"/>
    <child link="front_left_hip"/>
    <limit effort="4.0" lower="-1.04" upper="1.04" velocity="4.0"/>
    <joint_properties damping="0.0" friction="0.0"/>
  </joint>
  <link name="front_left_upper_leg">
    <visual>
      <origin rpy="0 0 1.5707963267948966" xyz="-0.252 -0.05 -0.055"/>
      <geometry>
        <mesh filename="package://stl/LEFT_UPPER_LEG.stl" scale="1 1 1"/>
      </geometry>
      <material name="black"/>
    </visual>
    <collision>
      <origin rpy="0 0 1.5707963267948966" xyz="0 0.02 -0.05"/>
      <geometry>
        <box size="0.035 0.035 0.11"/>
      </geometry>
    </collision>
    <inertial>
      <mass value="0.13"/>
      <origin rpy="0 0 0" xyz="-0.005 0.0175 -0.055"/>
      <!-- Inertial Axes -->
      <inertia ixx="0.00014435416666666668" ixy="0" ixz="0" iyx="0" iyy="0.00014435416666666668" iyz="0" izx="0" izy="0" izz="2.654166666666667e-05"/>
    </inertial>
  </link>
  <gazebo reference="front_left_upper_leg">
    <material>Gazebo/Black</material>
  </gazebo>
  <joint name="motor_front_left_upper_leg" type="revolute">
    <axis xyz="0 1 0"/>
    <origin rpy="0 0 0" xyz="0.0015 0.045 -0.0087"/>
    <parent link="front_left_hip"/>
    <child link="front_left_upper_leg"/>
    <limit effort="4.0" lower="-1.5707963267948966" upper="2.59" velocity="4.0"/>
    <joint_properties damping="0.0" friction="0.0"/>
  </joint>
  <link name="front_left_lower_leg">
    <visual>
      <origin rpy="0 0 1.5707963267948966" xyz="-0.247 -0.068 0.0535"/>
      <geometry>
        <mesh filename="package://stl/LEFT_LOWER_LEG.stl" scale="1 1 1"/>
      </geometry>
      <material name="black"/>
    </visual>
    <collision>
      <origin rpy="0 0 1.5707963267948966" xyz="0 0 -0.06"/>
      <geometry>
        <box size="0.035 0.035 0.12"/>
      </geometry>
    </collision>
    <inertial>
      <mass value="0.05"/>
      <origin rpy="0 0 0" xyz="-0.01 0 -0.06"/>
      <!-- Inertial Axes -->
      <inertia ixx="6.510416666666667e-05" ixy="0" ixz="0" iyx="0" iyy="6.510416666666667e-05" iyz="0" izx="0" izy="0" izz="1.0208333333333335e-05"/>
    </inertial>
  </link>
  <gazebo reference="front_left_lower_leg">
    <material>Gazebo/Black</material>
  </gazebo>
  <joint name="motor_front_left_lower_leg" type="revolute">
    <axis xyz="0 1 0"/>
    <origin rpy="0 0 0" xyz="-0.005 0.018 -0.109"/>
    <parent link="front_left_upper_leg"/>
    <child link="front_left_lower_leg"/>
    <limit effort="4.0" lower="-2.9" upper="1.5707963267948966" velocity="4.0"/>
    <joint_properties damping="0.0" friction="0.0"/>
  </joint>
  <link name="front_left_foot">
    <visual>
      <origin rpy="0 0 1.5707963267948966" xyz="-0.247 -0.068 0.18"/>
      <geometry>
        <mesh filename="package://stl/LEFT_FOOT.stl" scale="1 1 1"/>
      </geometry>
      <material name="orange"/>
    </visual>
    <collision>
      <origin rpy="0 0 1.5707963267948966" xyz="-0.247 -0.068 0.18"/>
      <geometry>
        <mesh filename="package://stl/LEFT_FOOT.stl" scale="1 1 1"/>
      </geometry>
      <contact_coefficients mu="10.1"/>
    </collision>
    <inertial>
      <mass value="0.005"/>
      <origin rpy="0 0 0" xyz="0 0 0"/>
      <!-- Inertial Axes -->
      <inertia ixx="3.5208333333333336e-06" ixy="0" ixz="0" iyx="0" iyy="2.8020833333333335e-06" iyz="0" izx="0" izy="0" izz="2.8020833333333335e-06"/>
    </inertial>
  </link>
  <gazebo reference="front_left_foot">
    <kp>1000000.0</kp>
    <kd>1.0</kd>
    <mu1>0.8</mu1>
    <mu2>0.8</mu2>
    <maxVel>0.0</maxVel>
    <minDepth>0.001</minDepth>
    <material>Gazebo/Orange</material>
  </gazebo>
  <joint name="front_left_leg_foot" type="fixed">
    <origin rpy="0 0 0" xyz="0 0 -0.1265"/>
    <parent link="front_left_lower_leg"/>
    <child link="front_left_foot"/>
  </joint>
  <link name="back_left_hip">
    <visual>
      <origin rpy="0 0 1.5707963267948966" xyz="-0.25 -0.0044 -0.067"/>
      <geometry>
        <mesh filename="package://stl/LEFT_HIP.stl" scale="1 1 1"/>
      </geometry>
      <material name="black"/>
    </visual>
    <collision>
      <origin rpy="0 0 1.5707963267948966" xyz="0.015 0.01 -0.01"/>
      <geometry>
        <box size="0.05 0.065 0.065"/>
      </geometry>
    </collision>
    <inertial>
      <mass value="0.2"/>
      <origin rpy="0 0 0" xyz="0 0.075 0"/>
      <!-- Inertial Axes -->
      <inertia ixx="0.00014083333333333336" ixy="0" ixz="0" iyx="0" iyy="0.00011208333333333335" iyz="0" izx="0" izy="0" izz="0.00011208333333333335"/>
    </inertial>
  </link>
  <gazebo reference="back_left_hip">
    <material>Gazebo/Black</material>
  </gazebo>
  <joint name="motor_back_left_hip" type="revolute">
    <axis xyz="1 0 0"/>
    <origin rpy="0 0 0" xyz="-0.1365 0.039400000000000004 0.022000000000000006"/>
    <parent link="back_bracket"/>
    <child link="back_left_hip"/>
    <limit effort="4.0" lower="-1.04" upper="1.04" velocity="4.0"/>
    <joint_properties damping="0.0" friction="0.0"/>
  </joint>
  <link name="back_left_upper_leg">
    <visual>
      <origin rpy="0 0 1.5707963267948966" xyz="-0.252 -0.05 -0.055"/>
      <geometry>
        <mesh filename="package://stl/LEFT_UPPER_LEG.stl" scale="1 1 1"/>
      </geometry>
      <material name="black"/>
    </visual>
    <collision>
      <origin rpy="0 0 1.5707963267948966" xyz="0 0.02 -0.05"/>
      <geometry>
        <box size="0.035 0.035 0.11"/>
      </geometry>
    </collision>
    <inertial>
      <mass value="0.13"/>
      <origin rpy="0 0 0" xyz="-0.005 0.0175 -0.055"/>
      <!-- Inertial Axes -->
      <inertia ixx="0.00014435416666666668" ixy="0" ixz="0" iyx="0" iyy="0.00014435416666666668" iyz="0" izx="0" izy="0" izz="2.654166666666667e-05"/>
    </inertial>
  </link>
  <gazebo reference="back_left_upper_leg">
    <material>Gazebo/Black</material>
  </gazebo>
  <joint name="motor_back_left_upper_leg" type="revolute">
    <axis xyz="0 1 0"/>
    <origin rpy="0 0 0" xyz="0.0015 0.045 -0.0087"/>
    <parent link="back_left_hip"/>
    <child link="back_left_upper_leg"/>
    <limit effort="4.0" lower="-1.5707963267948966" upper="2.59" velocity="4.0"/>
    <joint_properties damping="0.0" friction="0.0"/>
  </joint>
  <link name="back_left_lower_leg">
    <visual>
      <origin rpy="0 0 1.5707963267948966" xyz="-0.247 -0.068 0.0535"/>
      <geometry>
        <mesh filename="package://stl/LEFT_LOWER_LEG.stl" scale="1 1 1"/>
      </geometry>
      <material name="black"/>
    </visual>
    <collision>
      <origin rpy="0 0 1.5707963267948966" xyz="0 0 -0.06"/>
      <geometry>
        <box size="0.035 0.035 0.12"/>
      </geometry>
    </collision>
    <inertial>
      <mass value="0.05"/>
      <origin rpy="0 0 0" xyz="-0.01 0 -0.06"/>
      <!-- Inertial Axes -->
      <inertia ixx="6.510416666666667e-05" ixy="0" ixz="0" iyx="0" iyy="6.510416666666667e-05" iyz="0" izx="0" izy="0" izz="1.0208333333333335e-05"/>
    </inertial>
  </link>
  <gazebo reference="back_left_lower_leg">
    <material>Gazebo/Black</material>
  </gazebo>
  <joint name="motor_back_left_lower_leg" type="revolute">
    <axis xyz="0 1 0"/>
    <origin rpy="0 0 0" xyz="-0.005 0.018 -0.109"/>
    <parent link="back_left_upper_leg"/>
    <child link="back_left_lower_leg"/>
    <limit effort="4.0" lower="-2.9" upper="1.5707963267948966" velocity="4.0"/>
    <joint_properties damping="0.0" friction="0.0"/>
  </joint>
  <link name="back_left_foot">
    <visual>
      <origin rpy="0 0 1.5707963267948966" xyz="-0.247 -0.068 0.18"/>
      <geometry>
        <mesh filename="package://stl/LEFT_FOOT.stl" scale="1 1 1"/>
      </geometry>
      <material name="orange"/>
    </visual>
    <collision>
      <origin rpy="0 0 1.5707963267948966" xyz="-0.247 -0.068 0.18"/>
      <geometry>
        <mesh filename="package://stl/LEFT_FOOT.stl" scale="1 1 1"/>
      </geometry>
      <contact_coefficients mu="10.1"/>
    </collision>
    <inertial>
      <mass value="0.005"/>
      <origin rpy="0 0 0" xyz="0 0 0"/>
      <!-- Inertial Axes -->
      <inertia ixx="3.5208333333333336e-06" ixy="0" ixz="0" iyx="0" iyy="2.8020833333333335e-06" iyz="0" izx="0" izy="0" izz="2.8020833333333335e-06"/>
    </inertial>
  </link>
  <gazebo reference="back_left_foot">
    <kp>1000000.0</kp>
    <kd>1.0</kd>
    <mu1>0.8</mu1>
    <mu2>0.8</mu2>
    <maxVel>0.0</maxVel>
    <minDepth>0.001</minDepth>
    <material>Gazebo/Orange</material>
  </gazebo>
  <joint name="back_left_leg_foot" type="fixed">
    <origin rpy="0 0 0" xyz="0 0 -0.1265"/>
    <parent link="back_left_lower_leg"/>
    <child link="back_left_foot"/>
  </joint>
  <link name="front_right_hip">
    <visual>
      <origin rpy="0 0 1.5707963267948966" xyz="-0.25 0.074 -0.067"/>
      <geometry>
        <mesh filename="package://stl/RIGHT_HIP.stl" scale="1 1 1"/>
      </geometry>
      <material name="black"/>
    </visual>
    <collision>
      <origin rpy="0 0 1.5707963267948966" xyz="0.015 -0.01 -0.01"/>
      <geometry>
        <box size="0.05 0.065 0.065"/>
      </geometry>
    </collision>
    <inertial>
      <mass value="0.2"/>
      <origin rpy="0 0 0" xyz="0 -0.075 0"/>
      <!-- Inertial Axes -->
      <inertia ixx="0.00014083333333333336" ixy="0" ixz="0" iyx="0" iyy="0.00011208333333333335" iyz="0" izx="0" izy="0" izz="0.00011208333333333335"/>
    </inertial>
  </link>
  <gazebo reference="front_right_hip">
    <material>Gazebo/Black</material>
  </gazebo>
  <joint name="motor_front_right_hip" type="revolute">
    <axis xyz="1 0 0"/>
    <origin rpy="0 0 0" xyz="0.0915 -0.039400000000000004 0.022000000000000006"/>
    <parent link="front_bracket"/>
    <child link="front_right_hip"/>
    <limit effort="4.0" lower="-1.04" upper="1.04" velocity="4.0"/>
    <joint_properties damping="0.0" friction="0.0"/>
  </joint>
  <link name="front_right_upper_leg">
    <visual>
      <origin rpy="0 0 1.5707963267948966" xyz="-0.252 0.12 -0.055"/>
      <geometry>
        <mesh filename="package://stl/RIGHT_UPPER_LEG.stl" scale="1 1 1"/>
      </geometry>
      <material name="black"/>
    </visual>
    <collision>
      <origin rpy="0 0 1.5707963267948966" xyz="0 -0.02 -0.05"/>
      <geometry>
        <box size="0.035 0.035 0.11"/>
      </geometry>
    </collision>
    <inertial>
      <mass value="0.13"/>
      <origin rpy="0 0 0" xyz="-0.005 -0.0175 -0.055"/>
      <!-- Inertial Axes -->
      <inertia ixx="0.00014435416666666668" ixy="0" ixz="0" iyx="0" iyy="0.00014435416666666668" iyz="0" izx="0" izy="0" izz="2.654166666666667e-05"/>
    </inertial>
  </link>
  <gazebo reference="front_right_upper_leg">
    <material>Gazebo/Black</material>
  </gazebo>
  <joint name="motor_front_right_upper_leg" type="revolute">
    <axis xyz="0 1 0"/>
    <origin rpy="0 0 0" xyz="0.0015 -0.045 -0.0087"/>
    <parent link="front_right_hip"/>
    <child link="front_right_upper_leg"/>
    <limit effort="4.0" lower="-1.5707963267948966" upper="2.59" velocity="4.0"/>
    <joint_properties damping="0.0" friction="0.0"/>
  </joint>
  <link name="front_right_lower_leg">
    <visual>
      <origin rpy="0 0 1.5707963267948966" xyz="-0.247 0.138 0.0535"/>
      <geometry>
        <mesh filename="package://stl/RIGHT_LOWER_LEG.stl" scale="1 1 1"/>
      </geometry>
      <material name="black"/>
    </visual>
    <collision>
      <origin rpy="0 0 1.5707963267948966" xyz="0 0 -0.06"/>
      <geometry>
        <box size="0.035 0.035 0.12"/>
      </geometry>
    </collision>
    <inertial>
      <mass value="0.05"/>
      <origin rpy="0 0 0" xyz="-0.01 0 -0.06"/>
      <!-- Inertial Axes -->
      <inertia ixx="6.510416666666667e-05" ixy="0" ixz="0" iyx="0" iyy="6.510416666666667e-05" iyz="0" izx="0" izy="0" izz="1.0208333333333335e-05"/>
    </inertial>
  </link>
  <gazebo reference="front_right_lower_leg">
    <material>Gazebo/Black</material>
  </gazebo>
  <joint name="motor_front_right_lower_leg" type="revolute">
    <axis xyz="0 1 0"/>
    <origin rpy="0 0 0" xyz="-0.005 -0.018 -0.109"/>
    <parent link="front_right_upper_leg"/>
    <child link="front_right_lower_leg"/>
    <limit effort="4.0" lower="-2.9" upper="1.5707963267948966" velocity="4.0"/>
    <joint_properties damping="0.0" friction="0.0"/>
  </joint>
  <link name="front_right_foot">
    <visual>
      <origin rpy="0 0 1.5707963267948966" xyz="-0.247 0.138 0.18"/>
      <geometry>
        <mesh filename="package://stl/RIGHT_FOOT.stl" scale="1 1 1"/>
      </geometry>
      <material name="orange"/>
    </visual>
    <collision>
      <origin rpy="0 0 1.5707963267948966" xyz="-0.247 0.138 0.18"/>
      <geometry>
        <mesh filename="package://stl/RIGHT_FOOT.stl" scale="1 1 1"/>
      </geometry>
      <contact_coefficients mu="10.1"/>
    </collision>
    <inertial>
      <mass value="0.005"/>
      <origin rpy="0 0 0" xyz="0 0 0"/>
      <!-- Inertial Axes -->
      <inertia ixx="3.5208333333333336e-06" ixy="0" ixz="0" iyx="0" iyy="2.8020833333333335e-06" iyz="0" izx="0" izy="0" izz="2.8020833333333335e-06"/>
    </inertial>
  </link>
  <gazebo reference="front_right_foot">
    <kp>1000000.0</kp>
    <kd>1.0</kd>
    <mu1>0.8</mu1>
    <mu2>0.8</mu2>
    <maxVel>0.0</maxVel>
    <minDepth>0.001</minDepth>
    <material>Gazebo/Orange</material>
  </gazebo>
  <joint name="front_right_leg_foot" type="fixed">
    <origin rpy="0 0 0" xyz="0 0 -0.1265"/>
    <parent link="front_right_lower_leg"/>
    <child link="front_right_foot"/>
  </joint>
  <link name="back_right_hip">
    <visual>
      <origin rpy="0 0 1.5707963267948966" xyz="-0.25 0.074 -0.067"/>
      <geometry>
        <mesh filename="package://stl/RIGHT_HIP.stl" scale="1 1 1"/>
      </geometry>
      <material name="black"/>
    </visual>
    <collision>
      <origin rpy="0 0 1.5707963267948966" xyz="0.015 -0.01 -0.01"/>
      <geometry>
        <box size="0.05 0.065 0.065"/>
      </geometry>
    </collision>
    <inertial>
      <mass value="0.2"/>
      <origin rpy="0 0 0" xyz="0 -0.075 0"/>
      <!-- Inertial Axes -->
      <inertia ixx="0.00014083333333333336" ixy="0" ixz="0" iyx="0" iyy="0.00011208333333333335" iyz="0" izx="0" izy="0" izz="0.00011208333333333335"/>
    </inertial>
  </link>
  <gazebo reference="back_right_hip">
    <material>Gazebo/Black</material>
  </gazebo>
  <joint name="motor_back_right_hip" type="revolute">
    <axis xyz="1 0 0"/>
    <origin rpy="0 0 0" xyz="-0.1365 -0.039400000000000004 0.022000000000000006"/>
    <parent link="back_bracket"/>
    <child link="back_right_hip"/>
    <limit effort="4.0" lower="-1.04" upper="1.04" velocity="4.0"/>
    <joint_properties damping="0.0" friction="0.0"/>
  </joint>
  <link name="back_right_upper_leg">
    <visual>
      <origin rpy="0 0 1.5707963267948966" xyz="-0.252 0.12 -0.055"/>
      <geometry>
        <mesh filename="package://stl/RIGHT_UPPER_LEG.stl" scale="1 1 1"/>
      </geometry>
      <material name="black"/>
    </visual>
    <collision>
      <origin rpy="0 0 1.5707963267948966" xyz="0 -0.02 -0.05"/>
      <geometry>
        <box size="0.035 0.035 0.11"/>
      </geometry>
    </collision>
    <inertial>
      <mass value="0.13"/>
      <origin rpy="0 0 0" xyz="-0.005 -0.0175 -0.055"/>
      <!-- Inertial Axes -->
      <inertia ixx="0.00014435416666666668" ixy="0" ixz="0" iyx="0" iyy="0.00014435416666666668" iyz="0" izx="0" izy="0" izz="2.654166666666667e-05"/>
    </inertial>
  </link>
  <gazebo reference="back_right_upper_leg">
    <material>Gazebo/Black</material>
  </gazebo>
  <joint name="motor_back_right_upper_leg" type="revolute">
    <axis xyz="0 1 0"/>
    <origin rpy="0 0 0" xyz="0.0015 -0.045 -0.0087"/>
    <parent link="back_right_hip"/>
    <child link="back_right_upper_leg"/>
    <limit effort="4.0" lower="-1.5707963267948966" upper="2.59" velocity="4.0"/>
    <joint_properties damping="0.0" friction="0.0"/>
  </joint>
  <link name="back_right_lower_leg">
    <visual>
      <origin rpy="0 0 1.5707963267948966" xyz="-0.247 0.138 0.0535"/>
      <geometry>
        <mesh filename="package://stl/RIGHT_LOWER_LEG.stl" scale="1 1 1"/>
      </geometry>
      <material name="black"/>
    </visual>
    <collision>
      <origin rpy="0 0 1.5707963267948966" xyz="0 0 -0.06"/>
      <geometry>
        <box size="0.035 0.035 0.12"/>
      </geometry>
    </collision>
    <inertial>
      <mass value="0.05"/>
      <origin rpy="0 0 0" xyz="-0.01 0 -0.06"/>
      <!-- Inertial Axes -->
      <inertia ixx="6.510416666666667e-05" ixy="0" ixz="0" iyx="0" iyy="6.510416666666667e-05" iyz="0" izx="0" izy="0" izz="1.0208333333333335e-05"/>
    </inertial>
  </link>
  <gazebo reference="back_right_lower_leg">
    <material>Gazebo/Black</material>
  </gazebo>
  <joint name="motor_back_right_lower_leg" type="revolute">
    <axis xyz="0 1 0"/>
    <origin rpy="0 0 0" xyz="-0.005 -0.018 -0.109"/>
    <parent link="back_right_upper_leg"/>
    <child link="back_right_lower_leg"/>
    <limit effort="4.0" lower="-2.9" upper="1.5707963267948966" velocity="4.0"/>
    <joint_properties damping="0.0" friction="0.0"/>
  </joint>
  <link name="back_right_foot">
    <visual>
      <origin rpy="0 0 1.5707963267948966" xyz="-0.247 0.138 0.18"/>
      <geometry>
        <mesh filename="package://stl/RIGHT_FOOT.stl" scale="1 1 1"/>
      </geometry>
      <material name="orange"/>
    </visual>
    <collision>
      <origin rpy="0 0 1.5707963267948966" xyz="-0.247 0.138 0.18"/>
      <geometry>
        <mesh filename="package://stl/RIGHT_FOOT.stl" scale="1 1 1"/>
      </geometry>
      <contact_coefficients mu="10.1"/>
    </collision>
    <inertial>
      <mass value="0.005"/>
      <origin rpy="0 0 0" xyz="0 0 0"/>
      <!-- Inertial Axes -->
      <inertia ixx="3.5208333333333336e-06" ixy="0" ixz="0" iyx="0" iyy="2.8020833333333335e-06" iyz="0" izx="0" izy="0" izz="2.8020833333333335e-06"/>
    </inertial>
  </link>
  <gazebo reference="back_right_foot">
    <kp>1000000.0</kp>
    <kd>1.0</kd>
    <mu1>0.8</mu1>
    <mu2>0.8</mu2>
    <maxVel>0.0</maxVel>
    <minDepth>0.001</minDepth>
    <material>Gazebo/Orange</material>
  </gazebo>
  <joint name="back_right_leg_foot" type="fixed">
    <origin rpy="0 0 0" xyz="0 0 -0.1265"/>
    <parent link="back_right_lower_leg"/>
    <child link="back_right_foot"/>
  </joint>
  <joint name="base_base" type="fixed">
    <origin rpy="0 0 0" xyz="0 0 0"/>
    <parent link="base_link"/>
    <child link="base_inertia"/>
  </joint>
  <joint name="base_battery" type="fixed">
    <origin rpy="0 0 0" xyz="-0.01 0 -0.0225"/>
    <parent link="base_link"/>
    <child link="battery"/>
  </joint>
  <joint name="base_left" type="fixed">
    <origin rpy="0 0 0" xyz="0.00 0.052 0"/>
    <parent link="base_link"/>
    <child link="chassis_left"/>
  </joint>
  <joint name="base_right" type="fixed">
    <origin rpy="0 0 0" xyz="0.00 -0.052 0"/>
    <parent link="base_link"/>
    <child link="chassis_right"/>
  </joint>
  <joint name="base_front" type="fixed">
    <origin rpy="0 0 0" xyz="0 0 0"/>
    <parent link="base_link"/>
    <child link="front"/>
  </joint>
  <joint name="base_back" type="fixed">
    <origin rpy="0 0 0" xyz="0 0 0"/>
    <parent link="base_link"/>
    <child link="back"/>
  </joint>
  <joint name="base_front_bracket" type="fixed">
    <origin rpy="0 0 0" xyz="0 0 0"/>
    <parent link="base_link"/>
    <child link="front_bracket"/>
  </joint>
  <joint name="base_back_bracket" type="fixed">
    <origin rpy="0 0 0" xyz="0 0 0"/>
    <parent link="base_link"/>
    <child link="back_bracket"/>
  </joint>
  <transmission name="front_left_hip_joint_trans">
    <type>transmission_interface/SimpleTransmission</type>
    <joint name="motor_front_left_hip">
      <hardwareInterface>hardware_interface/EffortJointInterface</hardwareInterface>
    </joint>
    <actuator name="front_left_hip_joint_motor">
      <hardwareInterface>hardware_interface/EffortJointInterface</hardwareInterface>
      <mechanicalReduction>1</mechanicalReduction>
    </actuator>
  </transmission>
  <transmission name="front_left_upper_leg_joint_trans">
    <type>transmission_interface/SimpleTransmission</type>
    <joint name="motor_front_left_lower_leg">
      <hardwareInterface>hardware_interface/EffortJointInterface</hardwareInterface>
    </joint>
    <actuator name="front_left_upper_leg_joint_motor">
      <hardwareInterface>hardware_interface/EffortJointInterface</hardwareInterface>
      <mechanicalReduction>1</mechanicalReduction>
    </actuator>
  </transmission>
  <transmission name="front_left_lower_leg_joint_trans">
    <type>transmission_interface/SimpleTransmission</type>
    <joint name="motor_front_left_upper_leg">
      <hardwareInterface>hardware_interface/EffortJointInterface</hardwareInterface>
    </joint>
    <actuator name="front_left_lower_joint_motor">
      <hardwareInterface>hardware_interface/EffortJointInterface</hardwareInterface>
      <mechanicalReduction>1</mechanicalReduction>
    </actuator>
  </transmission>
  <transmission name="front_right_hip_joint_trans">
    <type>transmission_interface/SimpleTransmission</type>
    <joint name="motor_front_right_hip">
      <hardwareInterface>hardware_interface/EffortJointInterface</hardwareInterface>
    </joint>
    <actuator name="front_right_hip_joint_motor">
      <hardwareInterface>hardware_interface/EffortJointInterface</hardwareInterface>
      <mechanicalReduction>1</mechanicalReduction>
    </actuator>
  </transmission>
  <transmission name="front_right_upper_leg_joint_trans">
    <type>transmission_interface/SimpleTransmission</type>
    <joint name="motor_front_right_lower_leg">
      <hardwareInterface>hardware_interface/EffortJointInterface</hardwareInterface>
    </joint>
    <actuator name="front_right_upper_leg_joint_motor">
      <hardwareInterface>hardware_interface/EffortJointInterface</hardwareInterface>
      <mechanicalReduction>1</mechanicalReduction>
    </actuator>
  </transmission>
  <transmission name="front_right_lower_leg_joint_trans">
    <type>transmission_interface/SimpleTransmission</type>
    <joint name="motor_front_right_upper_leg">
      <hardwareInterface>hardware_interface/EffortJointInterface</hardwareInterface>
    </joint>
    <actuator name="front_right_lower_joint_motor">
      <hardwareInterface>hardware_interface/EffortJointInterface</hardwareInterface>
      <mechanicalReduction>1</mechanicalReduction>
    </actuator>
  </transmission>
  <transmission name="back_left_hip_joint_trans">
    <type>transmission_interface/SimpleTransmission</type>
    <joint name="motor_back_left_hip">
      <hardwareInterface>hardware_interface/EffortJointInterface</hardwareInterface>
    </joint>
    <actuator name="back_left_hip_joint_motor">
      <hardwareInterface>hardware_interface/EffortJointInterface</hardwareInterface>
      <mechanicalReduction>1</mechanicalReduction>
    </actuator>
  </transmission>
  <transmission name="back_left_upper_leg_joint_trans">
    <type>transmission_interface/SimpleTransmission</type>
    <joint name="motor_back_left_lower_leg">
      <hardwareInterface>hardware_interface/EffortJointInterface</hardwareInterface>
    </joint>
    <actuator name="back_left_upper_leg_joint_motor">
      <hardwareInterface>hardware_interface/EffortJointInterface</hardwareInterface>
      <mechanicalReduction>1</mechanicalReduction>
    </actuator>
  </transmission>
  <transmission name="back_left_lower_leg_joint_trans">
    <type>transmission_interface/SimpleTransmission</type>
    <joint name="motor_back_left_upper_leg">
      <hardwareInterface>hardware_interface/EffortJointInterface</hardwareInterface>
    </joint>
    <actuator name="back_left_lower_joint_motor">
      <hardwareInterface>hardware_interface/EffortJointInterface</hardwareInterface>
      <mechanicalReduction>1</mechanicalReduction>
    </actuator>
  </transmission>
  <transmission name="back_right_hip_joint_trans">
    <type>transmission_interface/SimpleTransmission</type>
    <joint name="motor_back_right_hip">
      <hardwareInterface>hardware_interface/EffortJointInterface</hardwareInterface>
    </joint>
    <actuator name="back_right_hip_joint_motor">
      <hardwareInterface>hardware_interface/EffortJointInterface</hardwareInterface>
      <mechanicalReduction>1</mechanicalReduction>
    </actuator>
  </transmission>
  <transmission name="back_right_upper_leg_joint_trans">
    <type>transmission_interface/SimpleTransmission</type>
    <joint name="motor_back_right_lower_leg">
      <hardwareInterface>hardware_interface/EffortJointInterface</hardwareInterface>
    </joint>
    <actuator name="back_right_upper_leg_joint_motor">
      <hardwareInterface>hardware_interface/EffortJointInterface</hardwareInterface>
      <mechanicalReduction>1</mechanicalReduction>
    </actuator>
  </transmission>
  <transmission name="back_right_lower_leg_joint_trans">
    <type>transmission_interface/SimpleTransmission</type>
    <joint name="motor_back_right_upper_leg">
      <hardwareInterface>hardware_interface/EffortJointInterface</hardwareInterface>
    </joint>
    <actuator name="back_right_lower_joint_motor">
      <hardwareInterface>hardware_interface/EffortJointInterface</hardwareInterface>
      <mechanicalReduction>1</mechanicalReduction>
    </actuator>
  </transmission>
  <gazebo>
    <plugin filename="libgazebo_ros_control.so" name="gazebo_ros_control">
      <robotNamespace>/spot</robotNamespace>
    </plugin>
  </gazebo>
</robot>
